Workbook

Sheet Assumptions
A1: FORSA EGYPT — KEY ASSUMPTIONS
A2: All figures in EGP unless noted | Blue = input, Black = formula
A4: Assumption | B4: Value | C4: Notes
A5: MARKET — CAIRO LAUNCH
A6: Total football academies in Cairo | B6: 500 | C6: Conservative estimate; actual ~400–600
A7: Total sports clinics in Cairo | B7: 120 | C7: MOH-licensed sports medicine clinics
A8: Target academy penetration — Yr1 | B8: 0.2 | C8: 20% = 100 academies
A9: Target clinic penetration — Yr1 | B9: 0.25 | C9: 25% = 30 clinics
A10: Parents registered — Yr1 | B10: 800 | C10: Conservative; word-of-mouth + referral
A11: Players registered — Yr1 | B11: 500 | C11: Including parent-managed child profiles
A13: PRICING
A14: Avg academy trial session fee (EGP) | B14: 250 | C14: Range: EGP 150–400 across Cairo
A15: Avg clinic appointment fee (EGP) | B15: 400 | C15: Range: EGP 300–600
A16: Commission rate — bookings | B16: 0.15 | C16: 15% of each completed booking
A17: Academy Pro subscription (EGP/mo) | B17: 299 | C17: Mid-tier; Elite = EGP 599
A18: Clinic Pro subscription (EGP/mo) | B18: 299 | C18: Same tier structure as academies
A19: Player premium (EGP/mo) | B19: 49 | C19: Verified badge + highlight hosting
A20: Parent premium (EGP/mo) | B20: 29 | C20: Booking credits + priority access
A21: Agent subscription (EGP/mo) | B21: 149 | C21: Player contacts + CRM tools
A23: BOOKING VOLUME
A24: Avg bookings per academy/month — Yr1 | B24: 3 | C24: Low at launch; increases with liquidity
A25: Avg bookings per academy/month — Yr2 | B25: 8 | C25: After referral flywheel
A26: Avg bookings per academy/month — Yr3 | B26: 15 | C26: Mature market
A27: Avg bookings per clinic/month — Yr1 | B27: 4 | C27: Clinics have more regular patients
A28: Avg bookings per clinic/month — Yr2 | B28: 10 | C28: After word-of-mouth
A29: Avg bookings per clinic/month — Yr3 | B29: 18 | C29: Mature
A31: SUBSCRIPTION TAKE-RATE
A32: % academies on paid plan — Yr1 | B32: 0.3 | C32: 30% upgrade after free tier
A33: % academies on paid plan — Yr2 | B33: 0.5 | C33: 50% as value becomes clear
A34: % academies on paid plan — Yr3 | B34: 0.65 | C34: 65% at maturity
A35: % clinics on paid plan — Yr1 | B35: 0.35 | C35: Higher than academies — more ROI-driven
A36: % clinics on paid plan — Yr2 | B36: 0.55
A37: % clinics on paid plan — Yr3 | B37: 0.7
A39: MONTHLY OPERATING COSTS (EGP)
A40: Hosting (AWS S3 + backend + Redis) | B40: 1500 | C40: Scales with volume from Yr2
A41: Payment gateway (Paymob) — base fee | B41: 500 | C41: Plus ~1.5% per transaction
A42: SMS OTP (Unifonic / Twilio) | B42: 800 | C42: ~EGP 0.40 per OTP; est. 2,000/mo
A43: WhatsApp Business API | B43: 500 | C43: Fixed + per-message fees
A44: Marketing — Google Ads | B44: 3000 | C44: Search ads in Arabic + English
A45: Marketing — Social content | B45: 4000 | C45: Content creator + video production
...

Sheet 3-Year P&L
A1: FORSA EGYPT — 3-YEAR PROFIT & LOSS PROJECTION
A2: EGP (Egyptian Pounds) | Conservative scenario
B4: Year 1 (2026) | C4: Year 2 (2027) | D4: Year 3 (2028) | E4: 3-Year Total
A5: REVENUE
A6: Booking Commission — Academies | B6: =Assumptions!B6*Assumptions!B8*Assumptions!B24*Assumptions!B14*Assumptions!B16 -> 11250 | C6: =Assumptions!B6*Assumptions!B53*Assumptions!B8*Assumptions!B25*Assumptions!B14*Assumptions!B16 -> 60000 | D6: =Assumptions!B6*Assumptions!B54*Assumptions!B8*Assumptions!B26*Assumptions!B14*Assumptions!B16 -> 196875 | E6: =B6+C6+D6 -> 268125
A7: Booking Commission — Clinics | B7: =Assumptions!B7*Assumptions!B9*Assumptions!B27*Assumptions!B15*Assumptions!B16 -> 7200 | C7: =Assumptions!B7*Assumptions!B52*Assumptions!B9*Assumptions!B28*Assumptions!B15*Assumptions!B16 -> 18000 | D7: =Assumptions!B7*Assumptions!B52*Assumptions!B9*Assumptions!B29*Assumptions!B15*Assumptions!B16 -> 32400 | E7: =B7+C7+D7 -> 57600
A8: Academy Subscriptions | B8: =Assumptions!B6*Assumptions!B8*Assumptions!B32*Assumptions!B17*12 -> 107640 | C8: =Assumptions!B6*Assumptions!B53*Assumptions!B8*Assumptions!B33*Assumptions!B17*12 -> 358800 | D8: =Assumptions!B6*Assumptions!B54*Assumptions!B8*Assumptions!B34*Assumptions!B17*12 -> 816270 | E8: =B8+C8+D8 -> 1282710
A9: Clinic Subscriptions | B9: =Assumptions!B7*Assumptions!B9*Assumptions!B35*Assumptions!B18*12 -> 37674 | C9: =Assumptions!B7*Assumptions!B52*Assumptions!B9*Assumptions!B36*Assumptions!B18*12 -> 59202 | D9: =Assumptions!B7*Assumptions!B52*Assumptions!B9*Assumptions!B37*Assumptions!B18*12 -> 75348 | E9: =B9+C9+D9 -> 172224
A10: Player Premium Subscriptions | B10: =Assumptions!B11*0.15*Assumptions!B19*12 -> 44100 | C10: =Assumptions!B11*Assumptions!B53*0.2*Assumptions!B19*12 -> 117600 | D10: =Assumptions!B11*Assumptions!B54*0.25*Assumptions!B19*12 -> 257250 | E10: =B10+C10+D10 -> 418950
A11: Parent Premium Subscriptions | B11: =Assumptions!B10*0.1*Assumptions!B20*12 -> 27840 | C11: =Assumptions!B10*Assumptions!B53*0.15*Assumptions!B20*12 -> 83520 | D11: =Assumptions!B10*Assumptions!B54*0.2*Assumptions!B20*12 -> 194880 | E11: =B11+C11+D11 -> 306240
A12: Agent Subscriptions | B12: =50*0.2*Assumptions!B21*12 -> 17880 | C12: =100*0.3*Assumptions!B21*12 -> 53640 | D12: =200*0.4*Assumptions!B21*12 -> 143040 | E12: =B12+C12+D12 -> 214560
A13: TOTAL REVENUE | B13: =SUM(B6:B12) -> 253584 | C13: =SUM(C6:C12) -> 750762 | D13: =SUM(D6:D12) -> 1716063 | E13: =SUM(E6:E12) -> 2720409
A15: COST OF REVENUE
A16: Payment gateway fees (1.5% of bookings) | B16: =-(B6+B7)*0.015 -> -276.75 | C16: =-(C6+C7)*0.015 -> -1170 | D16: =-(D6+D7)*0.015 -> -3439.125 | E16: =-(E6+E7)*0.015 -> -4885.875
A17: SMS / OTP costs | B17: =-Assumptions!B42*12 -> -9600 | C17: =-Assumptions!B42*12*1.5 -> -14400 | D17: =-Assumptions!B42*12*2 -> -19200 | E17: =B17+C17+D17 -> -43200
A18: GROSS PROFIT | B18: =B13+B16+B17 -> 243707.25 | C18: =C13+C16+C17 -> 735192 | D18: =D13+D16+D17 -> 1693423.9 | E18: =E13+E16+E17 -> 2672323.1
A20: OPERATING EXPENSES
A21: Hosting & Infrastructure | B21: =-Assumptions!B40*12 -> -18000 | C21: =-Assumptions!B40*12*1.4 -> -25200 | D21: =-Assumptions!B40*12*2 -> -36000 | E21: =B21+C21+D21 -> -79200
A22: WhatsApp Business API | B22: =-Assumptions!B43*12 -> -6000 | C22: =-Assumptions!B43*12 -> -6000 | D22: =-Assumptions!B43*12*1.5 -> -9000 | E22: =B22+C22+D22 -> -21000
A23: Marketing — Google Ads | B23: =-Assumptions!B44*12 -> -36000 | C23: =-Assumptions!B44*12*1.5 -> -54000 | D23: =-Assumptions!B44*12*2 -> -72000 | E23: =B23+C23+D23 -> -162000
A24: Marketing — Social/Content | B24: =-Assumptions!B45*12 -> -48000 | C24: =-Assumptions!B45*12*1.5 -> -72000 | D24: =-Assumptions!B45*12*2 -> -96000 | E24: =B24+C24+D24 -> -216000
A25: Events & Sponsorship | B25: =-Assumptions!B46*12 -> -90000 | C25: =-Assumptions!B46*12*1.5 -> -135000 | D25: =-Assumptions!B46*12*2 -> -180000 | E25: =B25+C25+D25 -> -405000
A26: Referral Program Credits | B26: =-Assumptions!B47*12 -> -36000 | C26: =-Assumptions!B47*12*1.5 -> -54000 | D26: =-Assumptions!B47*12*2 -> -72000 | E26: =B26+C26+D26 -> -162000
A27: Salaries & Operations | B27: =-Assumptions!B48*12 -> -180000 | C27: =-Assumptions!B48*12*2 -> -360000 | D27: =-Assumptions!B48*12*3 -> -540000 | E27: =B27+C27+D27 -> -1080000
A28: Misc / Legal / Contingency | B28: =-Assumptions!B49*12 -> -30000 | C28: =-Assumptions!B49*12*1.5 -> -45000 | D28: =-Assumptions!B49*12*2 -> -60000 | E28: =B28+C28+D28 -> -135000
A29: TOTAL OPEX | B29: =SUM(B21:B28) -> -444000 | C29: =SUM(C21:C28) -> -751200 | D29: =SUM(D21:D28) -> -1065000 | E29: =SUM(E21:E28) -> -2260200
A31: EBITDA | B31: =B18+B29 -> -200292.75 | C31: =C18+C29 -> -16008 | D31: =D18+D29 -> 628423.88 | E31: =E18+E29 -> 412123.12
A32: EBITDA Margin | B32: =IF(B13=0,0,B31/B13) -> -0.78984774 | C32: =IF(C13=0,0,C31/C13) -> -0.021322337 | D32: =IF(D13=0,0,D31/D13) -> 0.36620093 | E32: 3-Year Avg

Sheet Unit Economics
A1: FORSA EGYPT — UNIT ECONOMICS & BREAK-EVEN
A2: All in EGP | Cairo Year 1 baseline
A4: Metric | B4: Value | C4: How It's Calculated
A5: PER BOOKING ECONOMICS
A6: Avg academy booking value (EGP) | B6: =Assumptions!B14 -> 250 | C6: From Assumptions sheet
A7: Avg clinic booking value (EGP) | B7: =Assumptions!B15 -> 400 | C7: From Assumptions sheet
A8: Commission rate | B8: =Assumptions!B16 -> 0.15 | C8: 15% of booking value
A9: Revenue per academy booking (EGP) | B9: =B6*B8 -> 37.5 | C9: Forsa's share per transaction
A10: Revenue per clinic booking (EGP) | B10: =B7*B8 -> 60 | C10: Forsa's share per transaction
A11: Payment gateway cost per booking (1.5%) | B11: =-(B6*0.015) -> -3.75 | C11: Paymob fee deducted
A12: Net margin per academy booking (EGP) | B12: =B9+B11 -> 33.75 | C12: After gateway fees
A13: Net margin per clinic booking (EGP) | B13: =B10+B11 -> 56.25 | C13: After gateway fees
A15: CUSTOMER ACQUISITION COST (CAC)
A16: Blended CAC — Academy (EGP) | B16: 400 | C16: Door-to-door onboarding labor + photography
A17: Blended CAC — Parent (EGP) | B17: 35 | C17: WhatsApp + referral + ads blended
A18: Bookings to recover academy CAC | B18: =B16/B12 -> 11.851852 | C18: # of bookings to break even on CAC
A19: Bookings to recover parent CAC | B19: =B17/(B9*0.5) -> 1.8666667 | C19: Assuming parent books 50% of sessions
A21: LIFETIME VALUE (LTV) — YEAR 1
A22: Academy — avg bookings/month | B22: =Assumptions!B24 -> 3 | C22: From Assumptions
A23: Academy — avg subscription revenue/month (EGP) | B23: =Assumptions!B17*Assumptions!B32 -> 89.7 | C23: 30% take-rate × EGP 299
A24: Academy LTV — monthly revenue to Forsa (EGP) | B24: =B22*B9+B23 -> 202.2 | C24: Commission + subscription
A25: Academy LTV — 12-month (EGP) | B25: =B24*12 -> 2426.4 | C25: Annual LTV per academy
A26: Academy LTV/CAC ratio | B26: =B25/B16 -> 6.066 | C26: Target: >3×
A28: Parent — avg bookings/month | B28: 0.5 | C28: 1 booking every 2 months on average
A29: Parent — subscription revenue/month (EGP) | B29: =Assumptions!B20*0.1 -> 2.9 | C29: 10% take-rate on EGP 29 plan
A30: Parent LTV — monthly (EGP) | B30: =B28*B9*0.5+B29 -> 12.275 | C30: Half the booking via parent account
A31: Parent LTV — 12-month (EGP) | B31: =B30*12 -> 147.3 | C31: Annual LTV per parent
A32: Parent LTV/CAC ratio | B32: =B31/B17 -> 4.2085714 | C32: Target: >5×
A34: MONTHLY BREAK-EVEN ANALYSIS
A35: Fixed monthly costs (EGP) | B35: =Assumptions!B40+Assumptions!B42+Assumptions!B43+Assumptions!B44+Assumptions!B45+Assumptions!B46+Assumptions!B47+Assumptions!B48+Assumptions!B49 -> 37800 | C35: Sum of all monthly cost assumptions
A36: Variable cost per booking (payment gateway %) | B36: =Assumptions!B14*0.015 -> 3.75 | C36: Per academy booking
A37: Avg revenue per booking (net) | B37: =B9+B11 -> 33.75 | C37: Commission minus gateway fee
A38: Break-even bookings per month | B38: =ROUNDUP(B35/(B37),0) -> 1120 | C38: Fixed costs ÷ net margin per booking
A39: Break-even at avg 3 bookings/academy: academies needed | B39: =ROUNDUP(B38/Assumptions!B24,0) -> 374 | C39: Academies needed to break even
A40: Break-even month (est.) | B40: 12 | C40: Estimated month of first break-even

Sheet 90-Day Budget
A1: FORSA EGYPT — 90-DAY LAUNCH BUDGET
A2: All in EGP | Cairo launch only
A4: Item | B4: One-Time (EGP) | C4: Monthly (EGP) | D4: 3-Month Total (EGP) | E4: Category
A5: Academy onboarding (photography + ops) | B5: 8000 | D5: =B5+(C5*3) -> 8000 | E5: Operations
A6: Legal — ToS, Privacy Policy translation | B6: 5000 | D6: =B6+(C6*3) -> 5000 | E6: Legal
A7: Paymob payment gateway setup fee | B7: 2000 | C7: 500 | D7: =B7+(C7*3) -> 3500 | E7: Tech
A8: WhatsApp Business API setup | B8: 1500 | C8: 500 | D8: =B8+(C8*3) -> 3000 | E8: Tech
A9: Hosting (AWS S3 + backend + Redis) | C9: 1500 | D9: =B9+(C9*3) -> 4500 | E9: Tech
A10: SMS / OTP (Unifonic) | C10: 800 | D10: =B10+(C10*3) -> 2400 | E10: Tech
A11: Google Search Ads | C11: 3000 | D11: =B11+(C11*3) -> 9000 | E11: Marketing
A12: Instagram / TikTok content creation | C12: 4000 | D12: =B12+(C12*3) -> 12000 | E12: Marketing
A13: Youth tournament sponsorship | B13: 10000 | C13: 7500 | D13: =B13+(C13*3) -> 32500 | E13: Marketing
A14: Referral program credits (parents) | C14: 3000 | D14: =B14+(C14*3) -> 9000 | E14: Marketing
A15: Salaries — ops + part-time staff | C15: 15000 | D15: =B15+(C15*3) -> 45000 | E15: People
A16: Misc / contingency (10%) | C16: 2500 | D16: =B16+(C16*3) -> 7500 | E16: Misc
A17: TOTAL LAUNCH BUDGET | B17: =SUM(B5:B16) -> 26500 | C17: =SUM(C5:C16) -> 38300 | D17: =SUM(D5:D16) -> 141400
A19: Note: 3-Month Total = One-Time + (Monthly × 3). USD equivalent at EGP 50/USD: see total ÷ 50.
